Workbook

Sheet Data
A1: Rank | B1: Name | C1: Platform | D1: Year | E1: Genre | F1: Publisher | G1: Q1 | H1: Q2 | I1: Q3 | J1: Q4 | K1: Total Sales | L1: Discount % | M1: Total Discount | N1: Admin Cost % | O1: Admin Cost | P1: Net Total
A2: 1 | B2: Wii Sports | C2: Wii | D2: 2006 | E2: Sports | F2: Nintendo | G2: 29.02 | H2: 3.77 | I2: 8.46 | J2: 82.74 | K2: =SUM(G2:J2) -> 123.99 | L2: =IF(K2>20,10%,5%) -> 0.1 | M2: =K2*L2 -> 12.399 | N2: =LOOKUP(K2,Lookup!$A$2:$A$5,Lookup!$B$2:$B$5) -> 0.02 | O2: =K2*N2 -> 2.4798 | P2: =K2-M2+O2 -> 114.0708
A3: 2 | B3: Super Mario Bros. | C3: NES | D3: 1985 | E3: Platform | F3: Nintendo | G3: 3.58 | H3: 6.81 | I3: 0.77 | J3: 40.24 | K3: =SUM(G3:J3) -> 51.4 | L3: =IF(K3>20,10%,5%) -> 0.1 | M3: =K3*L3 -> 5.14 | N3: =LOOKUP(K3,Lookup!$A$2:$A$5,Lookup!$B$2:$B$5) -> 0.05 | O3: =K3*N3 -> 2.57 | P3: =K3-M3+O3 -> 48.83
A4: 3 | B4: Mario Kart Wii | C4: Wii | D4: 2008 | E4: Racing | F4: Nintendo | G4: 12.88 | H4: 3.79 | I4: 3.31 | J4: 35.82 | K4: =SUM(G4:J4) -> 55.8 | L4: =IF(K4>20,10%,5%) -> 0.1 | M4: =K4*L4 -> 5.58 | N4: =LOOKUP(K4,Lookup!$A$2:$A$5,Lookup!$B$2:$B$5) -> 0.05 | O4: =K4*N4 -> 2.79 | P4: =K4-M4+O4 -> 53.01
A5: 4 | B5: Wii Sports Resort | C5: Wii | D5: 2009 | E5: Sports | F5: Nintendo | G5: 11.01 | H5: 3.28 | I5: 2.96 | J5: 33 | K5: =SUM(G5:J5) -> 50.25 | L5: =IF(K5>20,10%,5%) -> 0.1 | M5: =K5*L5 -> 5.025 | N5: =LOOKUP(K5,Lookup!$A$2:$A$5,Lookup!$B$2:$B$5) -> 0.05 | O5: =K5*N5 -> 2.5125 | P5: =K5-M5+O5 -> 47.7375
A6: 5 | B6: Pokemon Red/Pokemon Blue | C6: GB | D6: 1996 | E6: Role-Playing | F6: Nintendo | G6: 8.89 | H6: 10.22 | I6: 1 | J6: 31.37 | K6: =SUM(G6:J6) -> 51.48 | L6: =IF(K6>20,10%,5%) -> 0.1 | M6: =K6*L6 -> 5.148 | N6: =LOOKUP(K6,Lookup!$A$2:$A$5,Lookup!$B$2:$B$5) -> 0.05 | O6: =K6*N6 -> 2.574 | P6: =K6-M6+O6 -> 48.906
A7: 6 | B7: Tetris | C7: GB | D7: 1989 | E7: Puzzle | F7: Nintendo | G7: 2.26 | H7: 4.22 | I7: 0.58 | J7: 30.26 | K7: =SUM(G7:J7) -> 37.32 | L7: =IF(K7>20,10%,5%) -> 0.1 | M7: =K7*L7 -> 3.732 | N7: =LOOKUP(K7,Lookup!$A$2:$A$5,Lookup!$B$2:$B$5) -> 0.08 | O7: =K7*N7 -> 2.9856 | P7: =K7-M7+O7 -> 36.5736
A8: 7 | B8: New Super Mario Bros. | C8: DS | D8: 2006 | E8: Platform | F8: Nintendo | G8: 9.23 | H8: 6.5 | I8: 2.9 | J8: 30.01 | K8: =SUM(G8:J8) -> 48.64 | L8: =IF(K8>20,10%,5%) -> 0.1 | M8: =K8*L8 -> 4.864 | N8: =LOOKUP(K8,Lookup!$A$2:$A$5,Lookup!$B$2:$B$5) -> 0.08 | O8: =K8*N8 -> 3.8912 | P8: =K8-M8+O8 -> 47.6672
A9: 8 | B9: Wii Play | C9: Wii | D9: 2006 | E9: Misc | F9: Nintendo | G9: 9.2 | H9: 2.93 | I9: 2.85 | J9: 29.02 | K9: =SUM(G9:J9) -> 44 | L9: =IF(K9>20,10%,5%) -> 0.1 | M9: =K9*L9 -> 4.4 | N9: =LOOKUP(K9,Lookup!$A$2:$A$5,Lookup!$B$2:$B$5) -> 0.08 | O9: =K9*N9 -> 3.52 | P9: =K9-M9+O9 -> 43.12
A10: 9 | B10: New Super Mario Bros. Wii | C10: Wii | D10: 2009 | E10: Platform | F10: Nintendo | G10: 7.06 | H10: 4.7 | I10: 2.26 | J10: 28.62 | K10: =SUM(G10:J10) -> 42.64 | L10: =IF(K10>20,10%,5%) -> 0.1 | M10: =K10*L10 -> 4.264 | N10: =LOOKUP(K10,Lookup!$A$2:$A$5,Lookup!$B$2:$B$5) -> 0.08 | O10: =K10*N10 -> 3.4112 | P10: =K10-M10+O10 -> 41.7872
A11: 10 | B11: Duck Hunt | C11: NES | D11: 1984 | E11: Shooter | F11: Nintendo | G11: 0.63 | H11: 0.28 | I11: 0.47 | J11: 28.31 | K11: =SUM(G11:J11) -> 29.69 | L11: =IF(K11>20,10%,5%) -> 0.1 | M11: =K11*L11 -> 2.969 | N11: =LOOKUP(K11,Lookup!$A$2:$A$5,Lookup!$B$2:$B$5) -> 0.08 | O11: =K11*N11 -> 2.3752 | P11: =K11-M11+O11 -> 29.0962
A12: 11 | B12: Nintendogs | C12: DS | D12: 2005 | E12: Simulation | F12: Nintendo | G12: 11 | H12: 1.93 | I12: 2.75 | J12: 24.76 | K12: =SUM(G12:J12) -> 40.44 | L12: =IF(K12>20,10%,5%) -> 0.1 | M12: =K12*L12 -> 4.044 | N12: =LOOKUP(K12,Lookup!$A$2:$A$5,Lookup!$B$2:$B$5) -> 0.08 | O12: =K12*N12 -> 3.2352 | P12: =K12-M12+O12 -> 39.6312
A13: 12 | B13: Mario Kart DS | C13: DS | D13: 2005 | E13: Racing | F13: Nintendo | G13: 7.57 | H13: 4.13 | I13: 1.92 | J13: 23.42 | K13: =SUM(G13:J13) -> 37.04 | L13: =IF(K13>20,10%,5%) -> 0.1 | M13: =K13*L13 -> 3.704 | N13: =LOOKUP(K13,Lookup!$A$2:$A$5,Lookup!$B$2:$B$5) -> 0.08 | O13: =K13*N13 -> 2.9632 | P13: =K13-M13+O13 -> 36.2992
... A90: 89 | B90: PokÃ©mon Platinum Version | C90: DS | D90: 2008 | E90: Role-Playing | F90: Nintendo | G90: 1.78 | H90: 2.69 | I90: 0.55 | J90: 7.84 | K90: =SUM(G90:J90) -> 12.86 | L90: =IF(K90>20,10%,5%) -> 0.05 | M90: =K90*L90 -> 0.643 | N90: =LOOKUP(K90,Lookup!$A$2:$A$5,Lookup!$B$2:$B$5) -> 0.1 | O90: =K90*N90 -> 1.286 | P90: =K90-M90+O90 -> 13.503
A91: 90 | B91: Pac-Man | C91: 2600 | D91: 1982 | E91: Puzzle | F91: Atari | G91: 0.45 | H91: 0 | I91: 0.08 | J91: 7.81 | K91: =SUM(G91:J91) -> 8.34 | L91: =IF(K91>20,10%,5%) -> 0.05 | M91: =K91*L91 -> 0.417 | N91: =LOOKUP(K91,Lookup!$A$2:$A$5,Lookup!$B$2:$B$5) -> 0.1 | O91: =K91*N91 -> 0.834 | P91: =K91-M91+O91 -> 8.757
A92: 91 | B92: Grand Theft Auto: Liberty City Stories | C92: PSP | D92: 2005 | E92: Action | F92: Take-Two Interactive | G92: 2.83 | H92: 0.24 | I92: 1.75 | J92: 7.72 | K92: =SUM(G92:J92) -> 12.54 | L92: =IF(K92>20,10%,5%) -> 0.05 | M92: =K92*L92 -> 0.627 | N92: =LOOKUP(K92,Lookup!$A$2:$A$5,Lookup!$B$2:$B$5) -> 0.1 | O92: =K92*N92 -> 1.254 | P92: =K92-M92+O92 -> 13.167
A93: 92 | B93: Super Mario Galaxy 2 | C93: Wii | D93: 2010 | E93: Platform | F93: Nintendo | G93: 2.42 | H93: 0.98 | I93: 0.64 | J93: 7.69 | K93: =SUM(G93:J93) -> 11.73 | L93: =IF(K93>20,10%,5%) -> 0.05 | M93: =K93*L93 -> 0.5865 | N93: =LOOKUP(K93,Lookup!$A$2:$A$5,Lookup!$B$2:$B$5) -> 0.1 | O93: =K93*N93 -> 1.173 | P93: =K93-M93+O93 -> 12.3165
A94: 93 | B94: Star Wars Battlefront (2015) | C94: PS4 | D94: 2015 | E94: Shooter | F94: Electronic Arts | G94: 3.29 | H94: 0.22 | I94: 1.23 | J94: 7.67 | K94: =SUM(G94:J94) -> 12.41 | L94: =IF(K94>20,10%,5%) -> 0.05 | M94: =K94*L94 -> 0.6205 | N94: =LOOKUP(K94,Lookup!$A$2:$A$5,Lookup!$B$2:$B$5) -> 0.1 | O94: =K94*N94 -> 1.241 | P94: =K94-M94+O94 -> 13.0305
A95: 94 | B95: Call of Duty: Advanced Warfare | C95: PS4 | D95: 2014 | E95: Shooter | F95: Activision | G95: 3.3 | H95: 0.14 | I95: 1.37 | J95: 7.6 | K95: =SUM(G95:J95) -> 12.41 | L95: =IF(K95>20,10%,5%) -> 0.05 | M95: =K95*L95 -> 0.6205 | N95: =LOOKUP(K95,Lookup!$A$2:$A$5,Lookup!$B$2:$B$5) -> 0.1 | O95: =K95*N95 -> 1.241 | P95: =K95-M95+O95 -> 13.0305
A96: 95 | B96: The Legend of Zelda: Ocarina of Time | C96: N64 | D96: 1998 | E96: Action | F96: Nintendo | G96: 1.89 | H96: 1.45 | I96: 0.16 | J96: 7.6 | K96: =SUM(G96:J96) -> 11.1 | L96: =IF(K96>20,10%,5%) -> 0.05 | M96: =K96*L96 -> 0.555 | N96: =LOOKUP(K96,Lookup!$A$2:$A$5,Lookup!$B$2:$B$5) -> 0.1 | O96: =K96*N96 -> 1.11 | P96: =K96-M96+O96 -> 11.655
A97: 96 | B97: Crash Bandicoot 2: Cortex Strikes Back | C97: PS | D97: 1997 | E97: Platform | F97: Sony Computer Entertainment | G97: 2.17 | H97: 1.31 | I97: 0.31 | J97: 7.58 | K97: =SUM(G97:J97) -> 11.37 | L97: =IF(K97>20,10%,5%) -> 0.05 | M97: =K97*L97 -> 0.5685 | N97: =LOOKUP(K97,Lookup!$A$2:$A$5,Lookup!$B$2:$B$5) -> 0.1 | O97: =K97*N97 -> 1.137 | P97: =K97-M97+O97 -> 11.9385
A98: 97 | B98: Super Mario Bros. 2 | C98: NES | D98: 1988 | E98: Platform | F98: Nintendo | G98: 1.18 | H98: 0.7 | I98: 0.19 | J98: 7.46 | K98: =SUM(G98:J98) -> 9.53 | L98: =IF(K98>20,10%,5%) -> 0.05 | M98: =K98*L98 -> 0.4765 | N98: =LOOKUP(K98,Lookup!$A$2:$A$5,Lookup!$B$2:$B$5) -> 0.1 | O98: =K98*N98 -> 0.953 | P98: =K98-M98+O98 -> 10.0065
A99: 98 | B99: Super Smash Bros. for Wii U and 3DS | C99: 3DS | D99: 2014 | E99: Fighting | F99: Nintendo | G99: 1.35 | H99: 2.42 | I99: 0.43 | J99: 7.45 | K99: =SUM(G99:J99) -> 11.65 | L99: =IF(K99>20,10%,5%) -> 0.05 | M99: =K99*L99 -> 0.5825 | N99: =LOOKUP(K99,Lookup!$A$2:$A$5,Lookup!$B$2:$B$5) -> 0.1 | O99: =K99*N99 -> 1.165 | P99: =K99-M99+O99 -> 12.2325
A100: 99 | B100: Call of Duty: World at War | C100: X360 | D100: 2008 | E100: Shooter | F100: Activision | G100: 1.9 | H100: 0 | I100: 0.69 | J100: 7.37 | K100: =SUM(G100:J100) -> 9.96 | L100: =IF(K100>20,10%,5%) -> 0.05 | M100: =K100*L100 -> 0.498 | N100: =LOOKUP(K100,Lookup!$A$2:$A$5,Lookup!$B$2:$B$5) -> 0.1 | O100: =K100*N100 -> 0.996 | P100: =K100-M100+O100 -> 10.458
A101: 100 | B101: Battlefield 3 | C101: X360 | D101: 2011 | E101: Shooter | F101: Electronic Arts | G101: 2.13 | H101: 0.06 | I101: 0.69 | J101: 7.34 | K101: =SUM(G101:J101) -> 10.22 | L101: =IF(K101>20,10%,5%) -> 0.05 | M101: =K101*L101 -> 0.511 | N101: =LOOKUP(K101,Lookup!$A$2:$A$5,Lookup!$B$2:$B$5) -> 0.1 | O101: =K101*N101 -> 1.022 | P101: =K101-M101+O101 -> 10.731
A102: 101 | B102: The Legend of Zelda: Twilight Princess | C102: Wii | D102: 2006 | E102: Action | F102: Nintendo | G102: 2.19 | H102: 0.6 | I102: 0.7 | J102: 7.31 | K102: =SUM(G102:J102) -> 10.8 | L102: =IF(K102>20,10%,5%) -> 0.05 | M102: =K102*L102 -> 0.54 | N102: =LOOKUP(K102,Lookup!$A$2:$A$5,Lookup!$B$2:$B$5) -> 0.1 | O102: =K102*N102 -> 1.08 | P102: =K102-M102+O102 -> 11.34
A103: 102 | B103: Call of Duty: Black Ops 3 | C103: XOne | D103: 2015 | E103: Shooter | F103: Activision | G103: 2.09 | H103: 0.01 | I103: 0.67 | J103: 7.3 | K103: =SUM(G103:J103) -> 10.07 | L103: =IF(K103>20,10%,5%) -> 0.05 | M103: =K103*L103 -> 0.5035 | N103: =LOOKUP(K103,Lookup!$A$2:$A$5,Lookup!$B$2:$B$5) -> 0.1 | O103: =K103*N103 -> 1.007 | P103: =K103-M103+O103 -> 10.5735
... A180: 179 | B180: Tomb Raider II | C180: PS | D180: 1997 | E180: Action | F180: Eidos Interactive | G180: 2.46 | H180: 0.2 | I180: 0.28 | J180: 5.24 | K180: =SUM(G180:J180) -> 8.18 | L180: =IF(K180>20,10%,5%) -> 0.05 | M180: =K180*L180 -> 0.409 | N180: =LOOKUP(K180,Lookup!$A$2:$A$5,Lookup!$B$2:$B$5) -> 0.1 | O180: =K180*N180 -> 0.818 | P180: =K180-M180+O180 -> 8.589
A181: 180 | B181: Madden NFL 2004 | C181: PS2 | D181: N/A | E181: Sports | F181: Electronic Arts | G181: 0.26 | H181: 0.01 | I181: 0.71 | J181: 5.23 | K181: =SUM(G181:J181) -> 6.21 | L181: =IF(K181>20,10%,5%) -> 0.05 | M181: =K181*L181 -> 0.3105 | N181: =LOOKUP(K181,Lookup!$A$2:$A$5,Lookup!$B$2:$B$5) -> 0.1 | O181: =K181*N181 -> 0.621 | P181: =K181-M181+O181 -> 6.5205
A182: 181 | B182: Dragon Quest VIII: Journey of the Cursed King | C182: PS2 | D182: 2004 | E182: Role-Playing | F182: Square Enix | G182: 0.75 | H182: 3.61 | I182: 0.2 | J182: 5.21 | K182: =SUM(G182:J182) -> 9.77 | L182: =IF(K182>20,10%,5%) -> 0.05 | M182: =K182*L182 -> 0.4885 | N182: =LOOKUP(K182,Lookup!$A$2:$A$5,Lookup!$B$2:$B$5) -> 0.1 | O182: =K182*N182 -> 0.977 | P182: =K182-M182+O182 -> 10.2585
A183: 182 | B183: Diablo III | C183: PC | D183: 2012 | E183: Role-Playing | F183: Activision | G183: 2.15 | H183: 0 | I183: 0.62 | J183: 5.2 | K183: =SUM(G183:J183) -> 7.97 | L183: =IF(K183>20,10%,5%) -> 0.05 | M183: =K183*L183 -> 0.3985 | N183: =LOOKUP(K183,Lookup!$A$2:$A$5,Lookup!$B$2:$B$5) -> 0.1 | O183: =K183*N183 -> 0.797 | P183: =K183-M183+O183 -> 8.3685
A184: 183 | B184: Super Mario Bros. 3 | C184: GBA | D184: 2003 | E184: Platform | F184: Nintendo | G184: 1.25 | H184: 0.83 | I184: 0.2 | J184: 5.2 | K184: =SUM(G184:J184) -> 7.48 | L184: =IF(K184>20,10%,5%) -> 0.05 | M184: =K184*L184 -> 0.374 | N184: =LOOKUP(K184,Lookup!$A$2:$A$5,Lookup!$B$2:$B$5) -> 0.1 | O184: =K184*N184 -> 0.748 | P184: =K184-M184+O184 -> 7.854
A185: 184 | B185: New Super Mario Bros. U | C185: WiiU | D185: 2012 | E185: Platform | F185: Nintendo | G185: 1.3 | H185: 1.27 | I185: 0.31 | J185: 5.19 | K185: =SUM(G185:J185) -> 8.07 | L185: =IF(K185>20,10%,5%) -> 0.05 | M185: =K185*L185 -> 0.4035 | N185: =LOOKUP(K185,Lookup!$A$2:$A$5,Lookup!$B$2:$B$5) -> 0.1 | O185: =K185*N185 -> 0.807 | P185: =K185-M185+O185 -> 8.4735
A186: 185 | B186: Super Mario Land 3: Wario Land | C186: GB | D186: 1994 | E186: Platform | F186: Nintendo | G186: 0.98 | H186: 1.57 | I186: 0.15 | J186: 5.19 | K186: =SUM(G186:J186) -> 7.89 | L186: =IF(K186>20,10%,5%) -> 0.05 | M186: =K186*L186 -> 0.3945 | N186: =LOOKUP(K186,Lookup!$A$2:$A$5,Lookup!$B$2:$B$5) -> 0.1 | O186: =K186*N186 -> 0.789 | P186: =K186-M186+O186 -> 8.2845
A187: 186 | B187: FIFA Soccer 13 | C187: X360 | D187: 2012 | E187: Action | F187: Electronic Arts | G187: 3.48 | H187: 0.03 | I187: 0.58 | J187: 5.18 | K187: =SUM(G187:J187) -> 9.27 | L187: =IF(K187>20,10%,5%) -> 0.05 | M187: =K187*L187 -> 0.4635 | N187: =LOOKUP(K187,Lookup!$A$2:$A$5,Lookup!$B$2:$B$5) -> 0.1 | O187: =K187*N187 -> 0.927 | P187: =K187-M187+O187 -> 9.7335
A188: 187 | B188: The Legend of Zelda: Phantom Hourglass | C188: DS | D188: 2007 | E188: Action | F188: Nintendo | G188: 1.83 | H188: 0.95 | I188: 0.49 | J188: 5.17 | K188: =SUM(G188:J188) -> 8.44 | L188: =IF(K188>20,10%,5%) -> 0.05 | M188: =K188*L188 -> 0.422 | N188: =LOOKUP(K188,Lookup!$A$2:$A$5,Lookup!$B$2:$B$5) -> 0.1 | O188: =K188*N188 -> 0.844 | P188: =K188-M188+O188 -> 8.862
A189: 188 | B189: Donkey Kong Country 2: Diddy's Kong Quest | C189: SNES | D189: 1995 | E189: Platform | F189: Nintendo | G189: 0.74 | H189: 2.2 | I189: 0.11 | J189: 5.15 | K189: =SUM(G189:J189) -> 8.2 | L189: =IF(K189>20,10%,5%) -> 0.05 | M189: =K189*L189 -> 0.41 | N189: =LOOKUP(K189,Lookup!$A$2:$A$5,Lookup!$B$2:$B$5) -> 0.1 | O189: =K189*N189 -> 0.82 | P189: =K189-M189+O189 -> 8.61
A190: 189 | B190: Tomodachi Life | C190: 3DS | D190: 2013 | E190: Simulation | F190: Nintendo | G190: 2.02 | H190: 1.89 | I190: 0.28 | J190: 5.15 | K190: =SUM(G190:J190) -> 9.34 | L190: =IF(K190>20,10%,5%) -> 0.05 | M190: =K190*L190 -> 0.467 | N190: =LOOKUP(K190,Lookup!$A$2:$A$5,Lookup!$B$2:$B$5) -> 0.1 | O190: =K190*N190 -> 0.934 | P190: =K190-M190+O190 -> 9.807
A191: 190 | B191: Mario & Sonic at the Olympic Games | C191: DS | D191: 2008 | E191: Sports | F191: Sega | G191: 2.48 | H191: 0.44 | I191: 0.58 | J191: 5.14 | K191: =SUM(G191:J191) -> 8.64 | L191: =IF(K191>20,10%,5%) -> 0.05 | M191: =K191*L191 -> 0.432 | N191: =LOOKUP(K191,Lookup!$A$2:$A$5,Lookup!$B$2:$B$5) -> 0.1 | O191: =K191*N191 -> 0.864 | P191: =K191-M191+O191 -> 9.072
A192: 191 | B192: Medal of Honor: Rising Sun | C192: PS2 | D192: 2003 | E192: Shooter | F192: Electronic Arts | G192: 2.23 | H192: 0.13 | I192: 0.8 | J192: 5.13 | K192: =SUM(G192:J192) -> 8.29 | L192: =IF(K192>20,10%,5%) -> 0.05 | M192: =K192*L192 -> 0.4145 | N192: =LOOKUP(K192,Lookup!$A$2:$A$5,Lookup!$B$2:$B$5) -> 0.1 | O192: =K192*N192 -> 0.829 | P192: =K192-M192+O192 -> 8.7045
...

Sheet Lookup
A1: Max Sales | B1: Admin Rate
A2: 0 | B2: 0.1
A3: 20 | B3: 0.08
A4: 50 | B4: 0.05
A5: 100 | B5: 0.02

Sheet Analysis
A1: Analysis for Shooter
A3: No. of Sales | B3: =COUNTIF(Data!E:E,"Shooter") -> 76
A4: Total Sales | B4: =SUMIF(Data!E:E,"Shooter",Data!K:K) -> 692.12
A5: Net Total | B5: =SUMIF(Data!E:E,"Shooter",Data!P:P) -> 718.5108
A6: Q1 Total | B6: =SUMIF(Data!E:E,"Shooter",Data!G:G) -> 143.52
A7: Q2 Total | B7: =SUMIF(Data!E:E,"Shooter",Data!H:H) -> 12.34
A8: Q3 Total | B8: =SUMIF(Data!E:E,"Shooter",Data!I:I) -> 49.14
A9: Q4 Total | B9: =SUMIF(Data!E:E,"Shooter",Data!J:J) -> 487.12
A10: Number of Net Totals > £20 | B10: =COUNTIFS(Data!E:E,"Shooter",Data!P:P,">20") -> 8
